[2022-09-08T11:41:22.280+0000] {taskinstance.py:1171} INFO - Dependencies all met for <TaskInstance: second_dag_v4.python_la_so_1 scheduled__2022-09-07T00:00:00+00:00 [queued]>
[2022-09-08T11:41:22.287+0000] {taskinstance.py:1171} INFO - Dependencies all met for <TaskInstance: second_dag_v4.python_la_so_1 scheduled__2022-09-07T00:00:00+00:00 [queued]>
[2022-09-08T11:41:22.288+0000] {taskinstance.py:1368} INFO - 
--------------------------------------------------------------------------------
[2022-09-08T11:41:22.289+0000] {taskinstance.py:1369} INFO - Starting attempt 1 of 6
[2022-09-08T11:41:22.290+0000] {taskinstance.py:1370} INFO - 
--------------------------------------------------------------------------------
[2022-09-08T11:41:22.298+0000] {taskinstance.py:1389} INFO - Executing <Task(PythonOperator): python_la_so_1> on 2022-09-07 00:00:00+00:00
[2022-09-08T11:41:22.302+0000] {standard_task_runner.py:52} INFO - Started process 2768 to run task
[2022-09-08T11:41:22.305+0000] {standard_task_runner.py:79} INFO - Running: ['***', 'tasks', 'run', 'second_dag_v4', 'python_la_so_1', 'scheduled__2022-09-07T00:00:00+00:00', '--job-id', '44', '--raw', '--subdir', 'DAGS_FOLDER/create_dag_with_python_operator.py', '--cfg-path', '/tmp/tmpx_x0ptc9', '--error-file', '/tmp/tmpj7m2ow8i']
[2022-09-08T11:41:22.306+0000] {standard_task_runner.py:80} INFO - Job 44: Subtask python_la_so_1
[2022-09-08T11:41:22.347+0000] {task_command.py:371} INFO - Running <TaskInstance: second_dag_v4.python_la_so_1 scheduled__2022-09-07T00:00:00+00:00 [running]> on host e458dbb0fb9f
[2022-09-08T11:41:22.393+0000] {taskinstance.py:1583} INFO - Exporting the following env vars:
AIRFLOW_CTX_DAG_OWNER=coder2j
AIRFLOW_CTX_DAG_ID=second_dag_v4
AIRFLOW_CTX_TASK_ID=python_la_so_1
AIRFLOW_CTX_EXECUTION_DATE=2022-09-07T00:00:00+00:00
AIRFLOW_CTX_TRY_NUMBER=1
AIRFLOW_CTX_DAG_RUN_ID=scheduled__2022-09-07T00:00:00+00:00
[2022-09-08T11:41:22.394+0000] {taskinstance.py:1902} ERROR - Task failed with exception
Traceback (most recent call last):
  File "/home/airflow/.local/lib/python3.7/site-packages/airflow/operators/python.py", line 171, in execute
    return_value = self.execute_callable()
  File "/home/airflow/.local/lib/python3.7/site-packages/airflow/operators/python.py", line 189, in execute_callable
    return self.python_callable(*self.op_args, **self.op_kwargs)
  File "/opt/airflow/dags/create_dag_with_python_operator.py", line 16, in first_function
    comment = ti.xcoms_pull(task_id = "python_la_so_1")
AttributeError: 'TaskInstance' object has no attribute 'xcoms_pull'
[2022-09-08T11:41:22.405+0000] {taskinstance.py:1412} INFO - Marking task as UP_FOR_RETRY. dag_id=second_dag_v4, task_id=python_la_so_1, execution_date=20220907T000000, start_date=20220908T114122, end_date=20220908T114122
[2022-09-08T11:41:22.420+0000] {standard_task_runner.py:97} ERROR - Failed to execute job 44 for task python_la_so_1 ('TaskInstance' object has no attribute 'xcoms_pull'; 2768)
[2022-09-08T11:41:22.437+0000] {local_task_job.py:156} INFO - Task exited with return code 1
[2022-09-08T11:41:22.458+0000] {local_task_job.py:279} INFO - 0 downstream tasks scheduled from follow-on schedule check
