[2022-09-08T11:46:29.064+0000] {taskinstance.py:1171} INFO - Dependencies all met for <TaskInstance: second_dag_v4.python_la_so_1 manual__2022-09-08T11:42:25.957774+00:00 [queued]>
[2022-09-08T11:46:29.070+0000] {taskinstance.py:1171} INFO - Dependencies all met for <TaskInstance: second_dag_v4.python_la_so_1 manual__2022-09-08T11:42:25.957774+00:00 [queued]>
[2022-09-08T11:46:29.071+0000] {taskinstance.py:1368} INFO - 
--------------------------------------------------------------------------------
[2022-09-08T11:46:29.071+0000] {taskinstance.py:1369} INFO - Starting attempt 3 of 6
[2022-09-08T11:46:29.072+0000] {taskinstance.py:1370} INFO - 
--------------------------------------------------------------------------------
[2022-09-08T11:46:29.080+0000] {taskinstance.py:1389} INFO - Executing <Task(PythonOperator): python_la_so_1> on 2022-09-08 11:42:25.957774+00:00
[2022-09-08T11:46:29.084+0000] {standard_task_runner.py:52} INFO - Started process 3178 to run task
[2022-09-08T11:46:29.086+0000] {standard_task_runner.py:79} INFO - Running: ['***', 'tasks', 'run', 'second_dag_v4', 'python_la_so_1', 'manual__2022-09-08T11:42:25.957774+00:00', '--job-id', '59', '--raw', '--subdir', 'DAGS_FOLDER/create_dag_with_python_operator.py', '--cfg-path', '/tmp/tmp7g997hjz', '--error-file', '/tmp/tmpsbdo3em9']
[2022-09-08T11:46:29.088+0000] {standard_task_runner.py:80} INFO - Job 59: Subtask python_la_so_1
[2022-09-08T11:46:29.126+0000] {task_command.py:371} INFO - Running <TaskInstance: second_dag_v4.python_la_so_1 manual__2022-09-08T11:42:25.957774+00:00 [running]> on host e458dbb0fb9f
[2022-09-08T11:46:29.297+0000] {taskinstance.py:1583} INFO - Exporting the following env vars:
AIRFLOW_CTX_DAG_OWNER=coder2j
AIRFLOW_CTX_DAG_ID=second_dag_v4
AIRFLOW_CTX_TASK_ID=python_la_so_1
AIRFLOW_CTX_EXECUTION_DATE=2022-09-08T11:42:25.957774+00:00
AIRFLOW_CTX_TRY_NUMBER=3
AIRFLOW_CTX_DAG_RUN_ID=manual__2022-09-08T11:42:25.957774+00:00
[2022-09-08T11:46:29.299+0000] {taskinstance.py:1902} ERROR - Task failed with exception
Traceback (most recent call last):
  File "/home/airflow/.local/lib/python3.7/site-packages/airflow/operators/python.py", line 171, in execute
    return_value = self.execute_callable()
  File "/home/airflow/.local/lib/python3.7/site-packages/airflow/operators/python.py", line 189, in execute_callable
    return self.python_callable(*self.op_args, **self.op_kwargs)
TypeError: first_function() missing 1 required positional argument: 'baaa'
[2022-09-08T11:46:29.305+0000] {taskinstance.py:1412} INFO - Marking task as UP_FOR_RETRY. dag_id=second_dag_v4, task_id=python_la_so_1, execution_date=20220908T114225, start_date=20220908T114629, end_date=20220908T114629
[2022-09-08T11:46:29.313+0000] {standard_task_runner.py:97} ERROR - Failed to execute job 59 for task python_la_so_1 (first_function() missing 1 required positional argument: 'baaa'; 3178)
[2022-09-08T11:46:29.343+0000] {local_task_job.py:156} INFO - Task exited with return code 1
[2022-09-08T11:46:29.363+0000] {local_task_job.py:279} INFO - 0 downstream tasks scheduled from follow-on schedule check
